<?xml version="1.0"?>
<robot name="inchworm">
  <link name="link_1">
    <inertial>
      <origin xyz="-0.0016917 -0.0012554 0.063867" rpy="0.0 0.0 0.0"/>
      <mass value="0.10777"/>
      <inertia ixx="3.8554e-05" ixy="9.4075e-07" ixz="1.709e-06" iyy="4.445e-05" iyz="1.2246e-06" izz="2.5729e-05"/>
    </inertial>
    <visual>
      <origin xyz="0.0 0.0 0.0" rpy="0.0 0.0 0.0"/>
      <geometry>
        <mesh filename="package://inchworm_description/meshes/link_1.STL"/>
      </geometry>
      <material name="">
        <color rgba="1.0 1.0 1.0 1.0"/>
      </material>
    </visual>
    <collision>
      <origin xyz="0.0 0.0 0.0" rpy="0.0 0.0 0.0"/>
      <geometry>
        <mesh filename="package://inchworm_description/meshes/link_1.STL"/>
      </geometry>
    </collision>
  </link>
  <link name="link_2">
    <inertial>
      <origin xyz="0.0033121 -0.0010932 -0.10202" rpy="0.0 0.0 0.0"/>
      <mass value="0.12376"/>
      <inertia ixx="5.6824e-05" ixy="-9.4075e-07" ixz="5.513e-07" iyy="7.822e-05" iyz="-1.2246e-06" izz="3.8675e-05"/>
    </inertial>
    <visual>
      <origin xyz="0.0 0.0 0.0" rpy="0.0 0.0 0.0"/>
      <geometry>
        <mesh filename="package://inchworm_description/meshes/link_2.STL"/>
      </geometry>
      <material name="">
        <color rgba="1.0 1.0 1.0 1.0"/>
      </material>
    </visual>
    <collision>
      <origin xyz="0.0 0.0 0.0" rpy="0.0 0.0 0.0"/>
      <geometry>
        <mesh filename="package://inchworm_description/meshes/link_2.STL"/>
      </geometry>
    </collision>
  </link>
  <joint name="joint_1" type="continuous">
    <origin xyz="0.0 -0.0002 0.10478" rpy="-3.1399 0.0 3.1416"/>
    <axis xyz="1.0 0.0 0.0"/>
    <parent link="link_1"/>
    <child link="link_2"/>
    <limit effort="30.0" lower="0.0" upper="0.0" velocity="0.0"/>
  </joint>
  <link name="link_3">
    <inertial>
      <origin xyz="0.026489 0.013907 -0.11702" rpy="0.0 0.0 0.0"/>
      <mass value="0.12376"/>
      <inertia ixx="5.6824e-05" ixy="-9.4075e-07" ixz="5.513e-07" iyy="7.822e-05" iyz="-1.2246e-06" izz="3.8675e-05"/>
    </inertial>
    <visual>
      <origin xyz="0.0 0.0 0.0" rpy="0.0 0.0 0.0"/>
      <geometry>
        <mesh filename="package://inchworm_description/meshes/link_3.STL"/>
      </geometry>
      <material name="">
        <color rgba="1.0 1.0 1.0 1.0"/>
      </material>
    </visual>
    <collision>
      <origin xyz="0.0 0.0 0.0" rpy="0.0 0.0 0.0"/>
      <geometry>
        <mesh filename="package://inchworm_description/meshes/link_3.STL"/>
      </geometry>
    </collision>
  </link>
  <joint name="joint_2" type="continuous">
    <origin xyz="-0.02165 -0.015204 -0.14832" rpy="0.00024788 0.0 0.0"/>
    <axis xyz="-1.0 0.0 0.0"/>
    <parent link="link_2"/>
    <child link="link_3"/>
    <limit effort="30.0" lower="0.0" upper="0.0" velocity="0.0"/>
  </joint>
  <link name="link_4">
    <inertial>
      <origin xyz="0.025131 0.015 -0.071936" rpy="0.0 0.0 0.0"/>
      <mass value="0.075697"/>
      <inertia ixx="2.7758e-05" ixy="9.4654e-18" ixz="-1.1577e-06" iyy="4.3258e-05" iyz="7.0031e-19" izz="3.2746e-05"/>
    </inertial>
    <visual>
      <origin xyz="0.0 0.0 0.0" rpy="0.0 0.0 0.0"/>
      <geometry>
        <mesh filename="package://inchworm_description/meshes/link_4.STL"/>
      </geometry>
      <material name="">
        <color rgba="1.0 1.0 1.0 1.0"/>
      </material>
    </visual>
    <collision>
      <origin xyz="0.0 0.0 0.0" rpy="0.0 0.0 0.0"/>
      <geometry>
        <mesh filename="package://inchworm_description/meshes/link_4.STL"/>
      </geometry>
    </collision>
  </link>
  <joint name="joint_3" type="continuous">
    <origin xyz="0.0017 -0.00017056 -0.16329" rpy="-0.0019608 0.0 0.0"/>
    <axis xyz="-1.0 0.0 0.0"/>
    <parent link="link_3"/>
    <child link="link_4"/>
    <limit effort="30.0" lower="0.0" upper="0.0" velocity="0.0"/>
  </joint>
</robot>
